<?xml version="1.0" encoding="utf-8"?>
<!-- =================================================================================== -->
<!-- |    This document was autogenerated by xacro from aqua.xacro                     | -->
<!-- |    EDITING THIS FILE BY HAND IS NOT RECOMMENDED                                 | -->
<!-- =================================================================================== -->
<robot name="aqua">

  <material name="gray">
    <color rgba="0.0 0.0 1.0 2.5"/>
  </material>
  <material name="red">
    <color rgba="0.0 0.0 1.0 2.5"/>
  </material>

  <link name="base_footprint" />
  
  <link name="base_link" />

  <joint name="body_joint" type="fixed">
    <origin rpy="0 0 0" xyz="0.0 0.0 0.0"/>
    <parent link="base_footprint"/>
    <child link="base_link"/>
  </joint>

  <joint name="body_joint" type="fixed">
    <origin rpy="0 0 0" xyz="-0.07 0 0.395"/>
    <parent link="base_link"/>
    <child link="body_link"/>
  </joint>

  <link name="body_link">
    <!-- <visual>
      <origin rpy="0 0 0" xyz="0 0 0"/>
      <geometry>
        <box size="0.49 0.34 0.405"/>
      </geometry>
      <material name="gray"/>
    </visual> -->
    <collision>
      <geometry>
        <box size="0.49 0.34 0.405" />
      </geometry>
    </collision>
    <intertial>
      <mass value="30.0" />
      <intertia ixx="0.69906" iyy="1.01031" izz="0.88925" ixy="0.0" ixz="0.0" iyz="0.0" />
    </intertial>
  </link>

  <joint name="left_wheel_joint" type="continuous">
    <origin rpy="-1.57079632679 0 0" xyz="0 0.215 0.1075"/>
    <parent link="base_link"/>
    <child link="left_wheel_link"/>
    <axis xyz="0 0 1"/>
  </joint>
  <link name="left_wheel_link">
    <!-- <visual>
      <geometry>
        <cylinder length="0.055" radius="0.1075"/>
      </geometry>
      <material name="red"/>
    </visual> -->
    <collision>
      <geometry>
        <cylinder length="0.055" radius="0.1075"/>
      </geometry>
    </collision>
    <intertial>
      <mass value="0.5" />
      <intertia ixx="0.00157" iyy="0.00157" izz="0.88925" ixy="0.0" ixz="0.0" iyz="0.0" />
    </intertial>
  </link>

  <joint name="right_wheel_joint" type="continuous">
    <origin rpy="-1.57079632679 0 0" xyz="0 -0.215 0.1075"/>
    <parent link="base_link"/>
    <child link="right_wheel_link"/>
    <axis xyz="0 0 1"/>
  </joint>
  <link name="right_wheel_link">
    <!-- <visual>
      <geometry>
        <cylinder length="0.055" radius="0.1075"/>
      </geometry>
      <material name="red"/>
    </visual> -->
    <collision>
      <geometry>
        <cylinder length="0.055" radius="0.1075"/>
      </geometry>
    </collision>
    <intertial>
      <mass value="0.5" />
      <intertia ixx="0.00157" iyy="0.00157" izz="0.88925" ixy="0.0" ixz="0.0" iyz="0.0" />
    </intertial>
  </link>

  <joint name="back_wheel_joint" type="continuous">
    <origin rpy="-1.57079632679 0 0" xyz="-0.25 0 0.1075"/>
    <parent link="base_link"/>
    <child link="back_wheel_link"/>
    <axis xyz="0 0 1"/>
  </joint>
  <link name="back_wheel_link">
    <!-- <visual>
      <geometry>
        <cylinder length="0.055" radius="0.1075"/>
      </geometry>
      <material name="red"/>
    </visual> -->
    <collision>
      <geometry>
        <cylinder length="0.055" radius="0.1075"/>
      </geometry>
    </collision>
    <intertial>
      <mass value="0.5" />
      <intertia ixx="0.00157" iyy="0.00157" izz="0.88925" ixy="0.0" ixz="0.0" iyz="0.0" />
    </intertial>
  </link>

  <joint name="scan_joint" type="fixed">
    <axis xyz="0 1 0" />
    <origin xyz="0 0 0.4" rpy="0 0 0" />
    <parent link="base_link" />
    <child link="base_scan" />
  </joint>
  <link name="base_scan">
    
  </link>

</robot>